2025-07-16 16:58:02,516 WARNING D:\workspace\python\our-family\api\app.py 71 - D:\workspace\python\our-family\api\uploaded_files, not exist, ready to create it...
2025-07-16 17:35:05,408 ERROR D:\workspace\python\our-family\api\app.py 54 - Traceback (most recent call last):
  File "C:\Users\Administrator\.virtualenvs\our-family-PzoeJut3\Lib\site-packages\flask\app.py", line 917, in full_dispatch_request
    rv = self.dispatch_request()
         ^^^^^^^^^^^^^^^^^^^^^^^
  File "C:\Users\Administrator\.virtualenvs\our-family-PzoeJut3\Lib\site-packages\flask\app.py", line 891, in dispatch_request
    self.raise_routing_exception(req)
  File "C:\Users\Administrator\.virtualenvs\our-family-PzoeJut3\Lib\site-packages\flask\app.py", line 500, in raise_routing_exception
    raise request.routing_exception  # type: ignore[misc]
    ^^^^^^^^^^^^^^^^^^^^^^^^^^^^^^^
  File "C:\Users\Administrator\.virtualenvs\our-family-PzoeJut3\Lib\site-packages\flask\ctx.py", line 362, in match_request
    result = self.url_adapter.match(return_rule=True)  # type: ignore
             ^^^^^^^^^^^^^^^^^^^^^^^^^^^^^^^^^^^^^^^^
  File "C:\Users\Administrator\.virtualenvs\our-family-PzoeJut3\Lib\site-packages\werkzeug\routing\map.py", line 629, in match
    raise NotFound() from None
werkzeug.exceptions.NotFound: 404 Not Found: The requested URL was not found on the server. If you entered the URL manually please check your spelling and try again.

2025-07-16 17:35:05,467 ERROR D:\workspace\python\our-family\api\app.py 54 - Traceback (most recent call last):
  File "C:\Users\Administrator\.virtualenvs\our-family-PzoeJut3\Lib\site-packages\flask\app.py", line 917, in full_dispatch_request
    rv = self.dispatch_request()
         ^^^^^^^^^^^^^^^^^^^^^^^
  File "C:\Users\Administrator\.virtualenvs\our-family-PzoeJut3\Lib\site-packages\flask\app.py", line 891, in dispatch_request
    self.raise_routing_exception(req)
  File "C:\Users\Administrator\.virtualenvs\our-family-PzoeJut3\Lib\site-packages\flask\app.py", line 500, in raise_routing_exception
    raise request.routing_exception  # type: ignore[misc]
    ^^^^^^^^^^^^^^^^^^^^^^^^^^^^^^^
  File "C:\Users\Administrator\.virtualenvs\our-family-PzoeJut3\Lib\site-packages\flask\ctx.py", line 362, in match_request
    result = self.url_adapter.match(return_rule=True)  # type: ignore
             ^^^^^^^^^^^^^^^^^^^^^^^^^^^^^^^^^^^^^^^^
  File "C:\Users\Administrator\.virtualenvs\our-family-PzoeJut3\Lib\site-packages\werkzeug\routing\map.py", line 629, in match
    raise NotFound() from None
werkzeug.exceptions.NotFound: 404 Not Found: The requested URL was not found on the server. If you entered the URL manually please check your spelling and try again.

2025-07-16 17:35:35,352 ERROR D:\workspace\python\our-family\api\app.py 54 - Traceback (most recent call last):
  File "C:\Users\Administrator\.virtualenvs\our-family-PzoeJut3\Lib\site-packages\flask\app.py", line 917, in full_dispatch_request
    rv = self.dispatch_request()
         ^^^^^^^^^^^^^^^^^^^^^^^
  File "C:\Users\Administrator\.virtualenvs\our-family-PzoeJut3\Lib\site-packages\flask\app.py", line 891, in dispatch_request
    self.raise_routing_exception(req)
  File "C:\Users\Administrator\.virtualenvs\our-family-PzoeJut3\Lib\site-packages\flask\app.py", line 500, in raise_routing_exception
    raise request.routing_exception  # type: ignore[misc]
    ^^^^^^^^^^^^^^^^^^^^^^^^^^^^^^^
  File "C:\Users\Administrator\.virtualenvs\our-family-PzoeJut3\Lib\site-packages\flask\ctx.py", line 362, in match_request
    result = self.url_adapter.match(return_rule=True)  # type: ignore
             ^^^^^^^^^^^^^^^^^^^^^^^^^^^^^^^^^^^^^^^^
  File "C:\Users\Administrator\.virtualenvs\our-family-PzoeJut3\Lib\site-packages\werkzeug\routing\map.py", line 629, in match
    raise NotFound() from None
werkzeug.exceptions.NotFound: 404 Not Found: The requested URL was not found on the server. If you entered the URL manually please check your spelling and try again.

2025-07-16 17:35:39,801 ERROR D:\workspace\python\our-family\api\app.py 54 - Traceback (most recent call last):
  File "C:\Users\Administrator\.virtualenvs\our-family-PzoeJut3\Lib\site-packages\flask\app.py", line 917, in full_dispatch_request
    rv = self.dispatch_request()
         ^^^^^^^^^^^^^^^^^^^^^^^
  File "C:\Users\Administrator\.virtualenvs\our-family-PzoeJut3\Lib\site-packages\flask\app.py", line 891, in dispatch_request
    self.raise_routing_exception(req)
  File "C:\Users\Administrator\.virtualenvs\our-family-PzoeJut3\Lib\site-packages\flask\app.py", line 500, in raise_routing_exception
    raise request.routing_exception  # type: ignore[misc]
    ^^^^^^^^^^^^^^^^^^^^^^^^^^^^^^^
  File "C:\Users\Administrator\.virtualenvs\our-family-PzoeJut3\Lib\site-packages\flask\ctx.py", line 362, in match_request
    result = self.url_adapter.match(return_rule=True)  # type: ignore
             ^^^^^^^^^^^^^^^^^^^^^^^^^^^^^^^^^^^^^^^^
  File "C:\Users\Administrator\.virtualenvs\our-family-PzoeJut3\Lib\site-packages\werkzeug\routing\map.py", line 629, in match
    raise NotFound() from None
werkzeug.exceptions.NotFound: 404 Not Found: The requested URL was not found on the server. If you entered the URL manually please check your spelling and try again.

